    return import_module("%s.base" % backend_name)
           ^^^^^^^^^^^^^^^^^^^^^^^^^^^^^^^^^^^^^^^
  File "C:\Users\Administrator\AppData\Local\Programs\Python\Python312\Lib\importlib\__init__.py", line 90, in import_module
    return _bootstrap._gcd_import(name[level:], package, level)
           ^^^^^^^^^^^^^^^^^^^^^^^^^^^^^^^^^^^^^^^^^^^^^^^^^^^^
  File "<frozen importlib._bootstrap>", line 1387, in _gcd_import
  File "<frozen importlib._bootstrap>", line 1360, in _find_and_load
  File "<frozen importlib._bootstrap>", line 1310, in _find_and_load_unlocked
  File "<frozen importlib._bootstrap>", line 488, in _call_with_frames_removed
  File "<frozen importlib._bootstrap>", line 1387, in _gcd_import
  File "<frozen importlib._bootstrap>", line 1360, in _find_and_load
  File "<frozen importlib._bootstrap>", line 1324, in _find_and_load_unlocked
ModuleNotFoundError: No module named 'mssql'

The above exception was the direct cause of the following exception:

Traceback (most recent call last):
  File "C:\BackendDAM\manage.py", line 22, in <module>
    main()
  File "C:\BackendDAM\manage.py", line 18, in main
    execute_from_command_line(sys.argv)
  File "C:\BackendDAM\venv\Lib\site-packages\django\core\management\__init__.py", line 442, in execute_from_command_line
    utility.execute()
  File "C:\BackendDAM\venv\Lib\site-packages\django\core\management\__init__.py", line 416, in execute
    django.setup()
  File "C:\BackendDAM\venv\Lib\site-packages\django\__init__.py", line 24, in setup
    apps.populate(settings.INSTALLED_APPS)
  File "C:\BackendDAM\venv\Lib\site-packages\django\apps\registry.py", line 116, in populate
    app_config.import_models()
  File "C:\BackendDAM\venv\Lib\site-packages\django\apps\config.py", line 269, in import_models
    self.models_module = import_module(models_module_name)
                         ^^^^^^^^^^^^^^^^^^^^^^^^^^^^^^^^^
  File "C:\Users\Administrator\AppData\Local\Programs\Python\Python312\Lib\importlib\__init__.py", line 90, in import_module
    return _bootstrap._gcd_import(name[level:], package, level)
           ^^^^^^^^^^^^^^^^^^^^^^^^^^^^^^^^^^^^^^^^^^^^^^^^^^^^
  File "<frozen importlib._bootstrap>", line 1387, in _gcd_import
  File "<frozen importlib._bootstrap>", line 1360, in _find_and_load
  File "<frozen importlib._bootstrap>", line 1331, in _find_and_load_unlocked
  File "<frozen importlib._bootstrap>", line 935, in _load_unlocked
  File "<frozen importlib._bootstrap_external>", line 999, in exec_module
  File "<frozen importlib._bootstrap>", line 488, in _call_with_frames_removed
  File "C:\BackendDAM\venv\Lib\site-packages\django\contrib\auth\models.py", line 5, in <module>
    from django.contrib.auth.base_user import AbstractBaseUser, BaseUserManager
  File "C:\BackendDAM\venv\Lib\site-packages\django\contrib\auth\base_user.py", line 43, in <module>
    class AbstractBaseUser(models.Model):
  File "C:\BackendDAM\venv\Lib\site-packages\django\db\models\base.py", line 145, in __new__
    new_class.add_to_class("_meta", Options(meta, app_label))
  File "C:\BackendDAM\venv\Lib\site-packages\django\db\models\base.py", line 373, in add_to_class
    value.contribute_to_class(cls, name)
  File "C:\BackendDAM\venv\Lib\site-packages\django\db\models\options.py", line 238, in contribute_to_class
    self.db_table, connection.ops.max_name_length()
                   ^^^^^^^^^^^^^^
  File "C:\BackendDAM\venv\Lib\site-packages\django\utils\connection.py", line 15, in __getattr__
    return getattr(self._connections[self._alias], item)
                   ~~~~~~~~~~~~~~~~~^^^^^^^^^^^^^
  File "C:\BackendDAM\venv\Lib\site-packages\django\utils\connection.py", line 62, in __getitem__
    conn = self.create_connection(alias)
           ^^^^^^^^^^^^^^^^^^^^^^^^^^^^^
  File "C:\BackendDAM\venv\Lib\site-packages\django\db\utils.py", line 193, in create_connection
    backend = load_backend(db["ENGINE"])
              ^^^^^^^^^^^^^^^^^^^^^^^^^^
  File "C:\BackendDAM\venv\Lib\site-packages\django\db\utils.py", line 126, in load_backend
    raise ImproperlyConfigured(
django.core.exceptions.ImproperlyConfigured: 'mssql' isn't an available database backend or couldn't be imported. Check the above exception. To use one of the built-in backends, use 'django.db.backends.XXX', where XXX is one of:
    'mysql', 'oracle', 'postgresql', 'sqlite3'
Starting Django development server...
Watching for file changes with StatReloader
Exception in thread django-main-thread:
Traceback (most recent call last):
  File "C:\BackendDAM\venv\Lib\site-packages\django\db\utils.py", line 113, in load_backend
    return import_module("%s.base" % backend_name)
           ^^^^^^^^^^^^^^^^^^^^^^^^^^^^^^^^^^^^^^^
  File "C:\Users\Administrator\AppData\Local\Programs\Python\Python312\Lib\importlib\__init__.py", line 90, in import_module
    return _bootstrap._gcd_import(name[level:], package, level)
           ^^^^^^^^^^^^^^^^^^^^^^^^^^^^^^^^^^^^^^^^^^^^^^^^^^^^
  File "<frozen importlib._bootstrap>", line 1387, in _gcd_import
  File "<frozen importlib._bootstrap>", line 1360, in _find_and_load
  File "<frozen importlib._bootstrap>", line 1310, in _find_and_load_unlocked
  File "<frozen importlib._bootstrap>", line 488, in _call_with_frames_removed
  File "<frozen importlib._bootstrap>", line 1387, in _gcd_import
  File "<frozen importlib._bootstrap>", line 1360, in _find_and_load
  File "<frozen importlib._bootstrap>", line 1324, in _find_and_load_unlocked
ModuleNotFoundError: No module named 'mssql'

The above exception was the direct cause of the following exception:

Traceback (most recent call last):
  File "C:\Users\Administrator\AppData\Local\Programs\Python\Python312\Lib\threading.py", line 1075, in _bootstrap_inner
    self.run()
  File "C:\Users\Administrator\AppData\Local\Programs\Python\Python312\Lib\threading.py", line 1012, in run
    self._target(*self._args, **self._kwargs)
  File "C:\BackendDAM\venv\Lib\site-packages\django\utils\autoreload.py", line 64, in wrapper
    fn(*args, **kwargs)
  File "C:\BackendDAM\venv\Lib\site-packages\django\core\management\commands\runserver.py", line 124, in inner_run
    autoreload.raise_last_exception()
  File "C:\BackendDAM\venv\Lib\site-packages\django\utils\autoreload.py", line 86, in raise_last_exception
    raise _exception[1]
  File "C:\BackendDAM\venv\Lib\site-packages\django\core\management\__init__.py", line 394, in execute
    autoreload.check_errors(django.setup)()
  File "C:\BackendDAM\venv\Lib\site-packages\django\utils\autoreload.py", line 64, in wrapper
    fn(*args, **kwargs)
  File "C:\BackendDAM\venv\Lib\site-packages\django\__init__.py", line 24, in setup
    apps.populate(settings.INSTALLED_APPS)
  File "C:\BackendDAM\venv\Lib\site-packages\django\apps\registry.py", line 116, in populate
    app_config.import_models()
  File "C:\BackendDAM\venv\Lib\site-packages\django\apps\config.py", line 269, in import_models
    self.models_module = import_module(models_module_name)
                         ^^^^^^^^^^^^^^^^^^^^^^^^^^^^^^^^^
  File "C:\Users\Administrator\AppData\Local\Programs\Python\Python312\Lib\importlib\__init__.py", line 90, in import_module
    return _bootstrap._gcd_import(name[level:], package, level)
           ^^^^^^^^^^^^^^^^^^^^^^^^^^^^^^^^^^^^^^^^^^^^^^^^^^^^
  File "<frozen importlib._bootstrap>", line 1387, in _gcd_import
  File "<frozen importlib._bootstrap>", line 1360, in _find_and_load
  File "<frozen importlib._bootstrap>", line 1331, in _find_and_load_unlocked
  File "<frozen importlib._bootstrap>", line 935, in _load_unlocked
  File "<frozen importlib._bootstrap_external>", line 999, in exec_module
  File "<frozen importlib._bootstrap>", line 488, in _call_with_frames_removed
  File "C:\BackendDAM\venv\Lib\site-packages\django\contrib\auth\models.py", line 5, in <module>
    from django.contrib.auth.base_user import AbstractBaseUser, BaseUserManager
  File "C:\BackendDAM\venv\Lib\site-packages\django\contrib\auth\base_user.py", line 43, in <module>
    class AbstractBaseUser(models.Model):
  File "C:\BackendDAM\venv\Lib\site-packages\django\db\models\base.py", line 145, in __new__
    new_class.add_to_class("_meta", Options(meta, app_label))
  File "C:\BackendDAM\venv\Lib\site-packages\django\db\models\base.py", line 373, in add_to_class
    value.contribute_to_class(cls, name)
  File "C:\BackendDAM\venv\Lib\site-packages\django\db\models\options.py", line 238, in contribute_to_class
    self.db_table, connection.ops.max_name_length()
                   ^^^^^^^^^^^^^^
  File "C:\BackendDAM\venv\Lib\site-packages\django\utils\connection.py", line 15, in __getattr__
    return getattr(self._connections[self._alias], item)
                   ~~~~~~~~~~~~~~~~~^^^^^^^^^^^^^
  File "C:\BackendDAM\venv\Lib\site-packages\django\utils\connection.py", line 62, in __getitem__
    conn = self.create_connection(alias)
           ^^^^^^^^^^^^^^^^^^^^^^^^^^^^^
  File "C:\BackendDAM\venv\Lib\site-packages\django\db\utils.py", line 193, in create_connection
    backend = load_backend(db["ENGINE"])
              ^^^^^^^^^^^^^^^^^^^^^^^^^^
  File "C:\BackendDAM\venv\Lib\site-packages\django\db\utils.py", line 126, in load_backend
    raise ImproperlyConfigured(
django.core.exceptions.ImproperlyConfigured: 'mssql' isn't an available database backend or couldn't be imported. Check the above exception. To use one of the built-in backends, use 'django.db.backends.XXX', where XXX is one of:
    'mysql', 'oracle', 'postgresql', 'sqlite3'